Workbook

Sheet Summary
A1: Datasets by modality and status
A2: Modality | B2: In store | C2: In pool, not prepared | D2: Access granted | E2: Public download | F2: Apply | G2: Candidate | H2: Unidentified | I2: Total
A3: CT | B3: =COUNTIFS(Datasets!$C$2:$C$66,$A3,Datasets!$E$2:$E$66,B$2) | C3: =COUNTIFS(Datasets!$C$2:$C$66,$A3,Datasets!$E$2:$E$66,C$2) | D3: =COUNTIFS(Datasets!$C$2:$C$66,$A3,Datasets!$E$2:$E$66,D$2) | E3: =COUNTIFS(Datasets!$C$2:$C$66,$A3,Datasets!$E$2:$E$66,E$2) | F3: =COUNTIFS(Datasets!$C$2:$C$66,$A3,Datasets!$E$2:$E$66,F$2) | G3: =COUNTIFS(Datasets!$C$2:$C$66,$A3,Datasets!$E$2:$E$66,G$2) | H3: =COUNTIFS(Datasets!$C$2:$C$66,$A3,Datasets!$E$2:$E$66,H$2) | I3: =SUM(B3:H3)
A4: MRI | B4: =COUNTIFS(Datasets!$C$2:$C$66,$A4,Datasets!$E$2:$E$66,B$2) | C4: =COUNTIFS(Datasets!$C$2:$C$66,$A4,Datasets!$E$2:$E$66,C$2) | D4: =COUNTIFS(Datasets!$C$2:$C$66,$A4,Datasets!$E$2:$E$66,D$2) | E4: =COUNTIFS(Datasets!$C$2:$C$66,$A4,Datasets!$E$2:$E$66,E$2) | F4: =COUNTIFS(Datasets!$C$2:$C$66,$A4,Datasets!$E$2:$E$66,F$2) | G4: =COUNTIFS(Datasets!$C$2:$C$66,$A4,Datasets!$E$2:$E$66,G$2) | H4: =COUNTIFS(Datasets!$C$2:$C$66,$A4,Datasets!$E$2:$E$66,H$2) | I4: =SUM(B4:H4)
A5: CT + MRI | B5: =COUNTIFS(Datasets!$C$2:$C$66,$A5,Datasets!$E$2:$E$66,B$2) | C5: =COUNTIFS(Datasets!$C$2:$C$66,$A5,Datasets!$E$2:$E$66,C$2) | D5: =COUNTIFS(Datasets!$C$2:$C$66,$A5,Datasets!$E$2:$E$66,D$2) | E5: =COUNTIFS(Datasets!$C$2:$C$66,$A5,Datasets!$E$2:$E$66,E$2) | F5: =COUNTIFS(Datasets!$C$2:$C$66,$A5,Datasets!$E$2:$E$66,F$2) | G5: =COUNTIFS(Datasets!$C$2:$C$66,$A5,Datasets!$E$2:$E$66,G$2) | H5: =COUNTIFS(Datasets!$C$2:$C$66,$A5,Datasets!$E$2:$E$66,H$2) | I5: =SUM(B5:H5)
A6: Total | B6: =SUM(B3:B5) | C6: =SUM(C3:C5) | D6: =SUM(D3:D5) | E6: =SUM(E3:E5) | F6: =SUM(F3:F5) | G6: =SUM(G3:G5) | H6: =SUM(H3:H5) | I6: =SUM(I3:I5)
A8: Store contents (datasets in store)
A9: Modality | B9: Subjects | C9: Volumes | D9: SSL pool volumes | E9: Test-split volumes
A10: CT | B10: =SUMIFS(Datasets!$F$2:$F$66,Datasets!$C$2:$C$66,$A10) | C10: =SUMIFS(Datasets!$G$2:$G$66,Datasets!$C$2:$C$66,$A10) | D10: =SUMIFS(Datasets!$H$2:$H$66,Datasets!$C$2:$C$66,$A10) | E10: =SUMIFS(Datasets!$I$2:$I$66,Datasets!$C$2:$C$66,$A10)
A11: MRI | B11: =SUMIFS(Datasets!$F$2:$F$66,Datasets!$C$2:$C$66,$A11) | C11: =SUMIFS(Datasets!$G$2:$G$66,Datasets!$C$2:$C$66,$A11) | D11: =SUMIFS(Datasets!$H$2:$H$66,Datasets!$C$2:$C$66,$A11) | E11: =SUMIFS(Datasets!$I$2:$I$66,Datasets!$C$2:$C$66,$A11)
A12: Total | B12: =SUM(B10:B11) | C12: =SUM(C10:C11) | D12: =SUM(D10:D11) | E12: =SUM(E10:E11)
A14: Evaluation tasks by status and modality
A15: Status | B15: CT | C15: MRI | D15: CT + MRI | E15: Total
A16: Benchmark v2 (classification / regression) | B16: =COUNTIFS('Eval tasks'!$J$2:$J$68,"Benchmark v2",'Eval tasks'!$C$2:$C$68,B$15) | C16: =COUNTIFS('Eval tasks'!$J$2:$J$68,"Benchmark v2",'Eval tasks'!$C$2:$C$68,C$15) | D16: =COUNTIFS('Eval tasks'!$J$2:$J$68,"Benchmark v2",'Eval tasks'!$C$2:$C$68,D$15) | E16: =SUM(B16:D16)
A17: Benchmark v2 (segmentation) | B17: =COUNTIFS('Eval tasks'!$J$2:$J$68,"Benchmark v2 (seg)",'Eval tasks'!$C$2:$C$68,B$15) | C17: =COUNTIFS('Eval tasks'!$J$2:$J$68,"Benchmark v2 (seg)",'Eval tasks'!$C$2:$C$68,C$15) | D17: =COUNTIFS('Eval tasks'!$J$2:$J$68,"Benchmark v2 (seg)",'Eval tasks'!$C$2:$C$68,D$15) | E17: =SUM(B17:D17)
A18: Suite only (excluded or not selected) | B18: =COUNTIFS('Eval tasks'!$J$2:$J$68,"Suite only*",'Eval tasks'!$C$2:$C$68,B$15) | C18: =COUNTIFS('Eval tasks'!$J$2:$J$68,"Suite only*",'Eval tasks'!$C$2:$C$68,C$15) | D18: =COUNTIFS('Eval tasks'!$J$2:$J$68,"Suite only*",'Eval tasks'!$C$2:$C$68,D$15) | E18: =SUM(B18:D18)
A19: Planned: needs data | B19: =COUNTIFS('Eval tasks'!$J$2:$J$68,"Planned*",'Eval tasks'!$C$2:$C$68,B$15) | C19: =COUNTIFS('Eval tasks'!$J$2:$J$68,"Planned*",'Eval tasks'!$C$2:$C$68,C$15) | D19: =COUNTIFS('Eval tasks'!$J$2:$J$68,"Planned*",'Eval tasks'!$C$2:$C$68,D$15) | E19: =SUM(B19:D19)
A20: Total | B20: =SUM(B16:B19) | C20: =SUM(C16:C19) | D20: =SUM(D16:D19) | E20: =SUM(E16:E19)

Sheet Datasets
A1: Dataset | B1: Store key | C1: Modality | D1: Contrasts (volumes) | E1: Status | F1: Subjects (store) | G1: Volumes (store) | H1: SSL pool volumes | I1: Test-split volumes | J1: Published size (approx.) | K1: Evaluation tasks | L1: Multitask training labels | M1: Access | N1: Source | O1: Overlaps and caveats
A2: RSNA Intracranial Hemorrhage 2019 | B2: rsna_ich | C2: CT | D2: ct (25082) | E2: In store | F2: 22305 | G2: 25082 | H2: 15358 | I2: 3272 | K2: rsna_ich | L2: SynthSeg morphometry (31 tasks); brain_asymmetry; brain_mask; brain_volume; ct_brain_density; ct_calcification; ct_csf_fraction; ct_gray_white_ratio; ct_skull_density; hemorrhage_any; hemorrhage_epidural; hemorrhage_intraparenchymal; hemorrhage_intraventricular; hemorrhage_subarachnoid; hemorrhage_subdural; intensity_asymmetry | N2: Kaggle / RSNA | O2: Hemorrhage labels trained by every BQ multitask model: rsna_ich is 'seen' for them. Open item: slice assembly / gantry tilt; QC-failed studies dropped from SSL.
A3: HemSeg-500 | B3: hemseg | C3: CT | D3: ct (517) | E3: In store | F3: 495 | G3: 517 | H3: 3 | I3: 64 | L3: brain_asymmetry; brain_mask; brain_volume; ct_brain_density; ct_calcification; ct_csf_fraction; ct_skull_density; hemorrhage_segmentation; intensity_asymmetry | N3: HemSeg-500 release | O3: RSNA studies with masks (dedup shares keys with rsna_ich).
A4: CQ500 (qure.ai) | B4: cq500 | C4: CT | D4: ct (519) | E4: In store | F4: 471 | G4: 519 | H4: 0 | I4: 80 | K4: cq500, cq500_bleed_side, cq500_chronic_bleed, cq500_edh, cq500_other_fracture, seg_cq500 (seg) | N4: qure.ai headctstudy | O4: Eval-only (pretrain=False). Re-converted from DICOM 2026-10-26. 48 volume ids collide with seg_cq500 (stopgap: ambiguous ids skipped).
A5: AISD (acute ischemic stroke, NCCT) | B5: aisd | C5: CT | D5: ct (398) | E5: In store | F5: 398 | G5: 398 | H5: 0 | I5: 52 | K5: aisd_remote_infarct, aisd (seg) | N5: AISD release
A6: BHSD (brain hemorrhage segmentation) | B6: bhsd | C6: CT | D6: ct (190) | E6: In store | F6: 189 | G6: 190 | H6: 0 | I6: 27 | L6: brain_asymmetry; brain_mask; brain_volume; ct_brain_density; ct_calcification; ct_csf_fraction; ct_skull_density; hemorrhage_segmentation; intensity_asymmetry | N6: BHSD release | O6: RSNA studies with masks (dedup shares keys with rsna_ich).
A7: ISLES 2024 (NCCT / CTA / CTP) | B7: isles24 | C7: CT | D7: cta (149), ct (149) | E7: In store | F7: 149 | G7: 298 | H7: 0 | I7: 44 | K7: isles24_mrs, isles24_mrs_discharge, isles24_lvo_side, isles24_nihss, isles24_nihss_discharge, isles24 (seg), isles24_cow (seg) | N7: ISLES'24 challenge | O7: Eval-only (pretrain=False).
A8: INSTANCE 2022 (ICH segmentation) | B8: instance | C8: CT | D8: ct (99) | E8: In store | F8: 99 | G8: 99 | H8: 0 | I8: 15 | K8: instance (seg) | N8: INSTANCE 2022 challenge | O8: Feeds hemorrhage_segmentation training: not transfer for BQ.
A9: BraTS glioma (2021 / 2023 / 2024 GLI) | B9: brats_gli | C9: MRI | D9: t1c (2864), t1 (2864), flair (2864), t2 (2864) | E9: In store | F9: 1829 | G9: 11456 | H9: 4812 | I9: 3176 | K9: gli_survival_12m, gli_lgg, gli_idh, brats2023_gli (seg), brats2024_gli (seg) | L9: SynthSeg morphometry (31 tasks); brain_asymmetry; brain_volume; enhancing_tumor; glioma_idh; glioma_lower_grade; glioma_survival_12m; intensity_asymmetry; resection_cavity; tumor_core; tumor_type; tumor_volume; whole_tumor | N9: Synapse (BraTS) | O9: TCGA subset carries IDH / grade / survival labels (gli_* tasks). UCSF-PDGM and UPENN-GBM patients overlap BraTS 2021.
A10: ATLAS v2.0 (chronic stroke T1) | B10: atlas | C10: MRI | D10: t1 (1448) | E10: In store | F10: 1448 | G10: 1448 | H10: 0 | I10: 217 | K10: atlas_lesion_side, atlas_lesion_volume, atlas_days_post_stroke, atlas (seg) | N10: ATLAS R2.0 (ICPSR / INDI) | O10: Eval-only (pretrain=False).
A11: ABIDE I | B11: abide1 | C11: MRI | D11: t1 (1101) | E11: In store | F11: 1101 | G11: 1101 | H11: 827 | I11: 164 | K11: abide_asd, abide_ados | L11: SynthSeg morphometry (31 tasks); autism_severity; brain_asymmetry; brain_mask; brain_volume; intensity_asymmetry | N11: INDI / FCP | O11: Train split in SSL pool; ADOS (autism_severity) labels exist for ASD subjects only.
A12: BraTS-MEN 2023 | B12: brats_men | C12: MRI | D12: t1c (1000), t1 (1000), flair (1000), t2 (1000) | E12: In store | F12: 944 | G12: 4000 | H12: 2812 | I12: 700 | K12: brats2023_men (seg) | L12: SynthSeg morphometry (31 tasks); brain_asymmetry; brain_volume; enhancing_tumor; intensity_asymmetry; tumor_core; tumor_type; tumor_volume; whole_tumor | N12: Synapse (BraTS)
A13: AOMIC ID1000 | B13: id1000 | C13: MRI | D13: t1 (928) | E13: In store | F13: 928 | G13: 928 | H13: 696 | I13: 139 | K13: id1000_age | L13: SynthSeg morphometry (31 tasks); brain_asymmetry; brain_mask; brain_volume; intensity_asymmetry | N13: OpenNeuro (AOMIC) | O13: Ages 19-26 only.
A14: IXI | B14: ixi | C14: MRI | D14: t1 (581), t2 (578) | E14: In store | F14: 582 | G14: 1159 | H14: 869 | I14: 174 | K14: ixi_age | L14: SynthSeg morphometry (32 tasks); brain_asymmetry; brain_mask; brain_volume; intensity_asymmetry | N14: brain-development.org
A15: OASIS-1 | B15: oasis1 | C15: MRI | D15: t1 (436) | E15: In store | F15: 416 | G15: 436 | H15: 307 | I15: 73 | K15: oasis1_cdr, oasis1_age, oasis1_mmse | L15: SynthSeg morphometry (31 tasks); brain_asymmetry; brain_mask; brain_volume; intensity_asymmetry; mmse | N15: oasis-brains.org | O15: Train split in SSL pool. Its 235 CDR-labelled subjects = BrainIAC's and BrainDINO's dementia cohort.
A16: BraTS-GoAT 2024 | B16: brats_goat | C16: MRI | D16: t1c (369), t2 (369), flair (367), t1 (366) | E16: In store | F16: 370 | G16: 1471 | H16: 1141 | I16: 175 | L16: SynthSeg morphometry (31 tasks); brain_asymmetry; brain_volume; intensity_asymmetry | N16: Synapse (BraTS)
A17: ISLES 2022 (DWI / ADC / FLAIR) | B17: isles22 | C17: MRI | D17: adc (249), flair (249), dwi (248) | E17: In store | F17: 249 | G17: 746 | H17: 0 | I17: 114 | K17: isles22 (seg) | N17: ISLES'22 (Zenodo)
A18: AOMIC PIOP2 | B18: piop2 | C18: MRI | D18: t1 (226) | E18: In store | F18: 226 | G18: 226 | H18: 169 | I18: 34 | K18: piop2_age | L18: SynthSeg morphometry (31 tasks); brain_asymmetry; brain_mask; brain_volume; intensity_asymmetry | N18: OpenNeuro (AOMIC) | O18: Ages 18-26 only.
A19: AOMIC PIOP1 | B19: piop1 | C19: MRI | D19: t1 (216) | E19: In store | F19: 216 | G19: 216 | H19: 162 | I19: 32 | K19: piop1_age | L19: SynthSeg morphometry (31 tasks); brain_asymmetry; brain_mask; brain_volume; intensity_asymmetry | N19: OpenNeuro (AOMIC) | O19: Ages 18-26 only.
A20: WMH Segmentation Challenge 2017 | B20: wmh | C20: MRI | D20: flair (170), t1 (170) | E20: In store | F20: 170 | G20: 340 | H20: 0 | I20: 52 | K20: wmh (seg) | N20: WMH challenge (DataverseNL)
A21: BrainMetShare (Stanford) | B21: brainmetshare | C21: MRI | D21: t1c (312), t1 (156), flair (156) | E21: In store | F21: 156 | G21: 624 | H21: 0 | I21: 92 | N21: Stanford AIMI
A22: Pixar (OpenNeuro ds000228) | B22: pixar | C22: MRI | D22: t1 (155) | E22: In store | F22: 155 | G22: 155 | H22: 116 | I22: 23 | K22: pixar_age | L22: SynthSeg morphometry (31 tasks); brain_asymmetry; brain_mask; brain_volume; intensity_asymmetry | N22: OpenNeuro ds000228
A23: OASIS-2 (longitudinal) | B23: oasis2 | C23: MRI | D23: t1 (373) | E23: In store | F23: 150 | G23: 373 | H23: 75 | I23: 140 | K23: oasis2_cdr, oasis2_conversion, oasis2_mmse | L23: SynthSeg morphometry (31 tasks); brain_asymmetry; brain_mask; brain_volume; intensity_asymmetry; mmse | N23: oasis-brains.org
A24: BraTS-PED 2023 | B24: brats_ped | C24: MRI | D24: t1c (143), t1 (143), flair (143), t2 (143) | E24: In store | F24: 143 | G24: 572 | H24: 428 | I24: 88 | K24: brats2023_ped (seg) | L24: SynthSeg morphometry (31 tasks); brain_asymmetry; brain_volume; intensity_asymmetry; tumor_type; tumor_volume; whole_tumor | N24: Synapse (BraTS)
A25: MSD Task01 BrainTumour (non-BraTS remainder) | B25: msd_braintumor | C25: MRI | D25: t1 (115) | E25: In store | F25: 115 | G25: 115 | H25: 0 | I25: 16 | K25: msd | N25: Medical Segmentation Decathlon | O25: MSD copies of BraTS 2017 cases were removed by content dedup; 115 remain.
A26: MS3SEG | B26: ms3seg | C26: MRI | D26: flair (100), t1 (100), t2 (100) | E26: In store | F26: 100 | G26: 300 | H26: 0 | I26: 45 | K26: ms3seg_age, ms3seg_lesion_load, ms3seg (seg) | N26: figshare
A27: VALDO 2021 (small vessel disease) | B27: valdo | C27: MRI | D27: t1 (152), t2 (146), flair (80), t2s (72) | E27: In store | F27: 72 | G27: 450 | H27: 0 | I27: 63 | K27: valdo_epvs, valdo_cmb (seg), valdo_lacunes (seg) | N27: VALDO (Zenodo) | O27: Eval-only (pretrain=False).
A28: Healthy Brain Network (FOMO) | B28: fomo_hbn | C28: MRI | D28: t1 (3763), t2 (2806), pd (1183), flair (726) | E28: In store | F28: 3841 | G28: 8478 | H28: 5461 | I28: 1280 | L28: SynthSeg morphometry (32 tasks); age; brain_asymmetry; brain_mask; brain_volume; intensity_asymmetry; sex | N28: FOMO-260K compilation
A29: CoRR (FOMO) | B29: fomo_corr | C29: MRI | D29: t1 (2686) | E29: In store | F29: 1472 | G29: 2686 | H29: 1103 | I29: 398 | L29: SynthSeg morphometry (31 tasks); age; brain_asymmetry; brain_mask; brain_volume; intensity_asymmetry; sex | N29: FOMO-260K compilation
A30: Yale brain metastases (FOMO) | B30: fomo_yale_mets | C30: MRI | D30: flair (9076), t1c (8992), t1 (8235), t2 (7325), pd (53) | E30: In store | F30: 1430 | G30: 33681 | H30: 3972 | I30: 5194 | L30: SynthSeg morphometry (31 tasks); age; brain_asymmetry; brain_volume; intensity_asymmetry; sex; tumor_type | N30: FOMO-260K compilation
A31: NKI-Rockland (FOMO) | B31: fomo_nki | C31: MRI | D31: t1 (2453), flair (2359), t2 (1136) | E31: In store | F31: 1326 | G31: 5948 | H31: 2354 | I31: 907 | L31: SynthSeg morphometry (32 tasks); age; brain_asymmetry; brain_mask; brain_volume; intensity_asymmetry; sex | N31: FOMO-260K compilation
A32: Infant MRI (FOMO) | B32: fomo_infant | C32: MRI | D32: t2 (833), t1 (832) | E32: In store | F32: 833 | G32: 1665 | H32: 1110 | I32: 250 | L32: SynthSeg morphometry (31 tasks); age; brain_asymmetry; brain_mask; brain_volume; infant_abnormal; intensity_asymmetry | N32: FOMO-260K compilation
A33: SLIM longitudinal (FOMO) | B33: fomo_slim | C33: MRI | D33: t1 (1037) | E33: In store | F33: 588 | G33: 1037 | H33: 441 | I33: 154 | L33: SynthSeg morphometry (31 tasks); age; brain_asymmetry; brain_mask; brain_volume; intensity_asymmetry; sex | N33: FOMO-260K compilation
A34: BrainLat (FOMO) | B34: fomo_brainlat | C34: MRI | D34: t1 (576), flair (45) | E34: In store | F34: 576 | G34: 621 | H34: 462 | I34: 95 | L34: SynthSeg morphometry (32 tasks); age; brain_asymmetry; brain_mask; brain_volume; intensity_asymmetry; neuro_diagnosis; parkinsons; sex | N34: FOMO-260K compilation
A35: FOMO cohort: wayne | B35: fomo_wayne | C35: MRI | D35: t1 (610) | E35: In store | F35: 426 | G35: 610 | H35: 319 | I35: 102 | L35: SynthSeg morphometry (31 tasks); age; brain_asymmetry; brain_mask; brain_volume; intensity_asymmetry; sex | N35: FOMO-260K compilation
A36: FOMO cohort: yale_highres | B36: fomo_yale_highres | C36: MRI | D36: t1 (268) | E36: In store | F36: 232 | G36: 268 | H36: 174 | I36: 41 | L36: SynthSeg morphometry (31 tasks); age; brain_asymmetry; brain_mask; brain_volume; intensity_asymmetry; sex | N36: FOMO-260K compilation
A37: M4Raw low-field (FOMO) | B37: fomo_m4raw | C37: MRI | D37: flair (208), t1 (208), t2 (208) | E37: In store | F37: 208 | G37: 624 | H37: 468 | I37: 93 | L37: SynthSeg morphometry (32 tasks); brain_asymmetry; brain_mask; brain_volume; intensity_asymmetry | N37: FOMO-260K compilation
A38: Cuban Human Brain Mapping (FOMO) | B38: fomo_chbmp | C38: MRI | D38: t1 (203) | E38: In store | F38: 203 | G38: 203 | H38: 153 | I38: 30 | L38: SynthSeg morphometry (31 tasks); age; brain_asymmetry; brain_mask; brain_volume; intensity_asymmetry; sex | N38: FOMO-260K compilation
A39: FOMO cohort: beijing | B39: fomo_beijing | C39: MRI | D39: t1 (180) | E39: In store | F39: 180 | G39: 180 | H39: 135 | I39: 27 | L39: SynthSeg morphometry (31 tasks); brain_asymmetry; brain_mask; brain_volume; intensity_asymmetry; sex | N39: FOMO-260K compilation
... A50: FOMO cohort: hbnssi | B50: fomo_hbnssi | C50: MRI | D50: t1 (167), t2 (12) | E50: In store | F50: 13 | G50: 179 | H50: 19 | I50: 28 | L50: SynthSeg morphometry (31 tasks); age; brain_asymmetry; brain_mask; brain_volume; intensity_asymmetry; sex | N50: FOMO-260K compilation
...

Sheet Eval tasks
A1: Task | B1: Dataset | C1: Modality | D1: Type | E1: Labels | F1: Labelled scans | G1: Positives | H1: Label range | I1: Test-split scans | J1: Status | K1: Benchmark group | L1: Metric | M1: BQ-R6 | N1: BQ-v3 | O1: BQ-random | P1: Best published | Q1: Best published score | R1: Literature comparators | S1: Notes
A2: aisd_remote_infarct | B2: AISD (acute ischemic stroke, NCCT) | C2: CT | D2: binary | E2: remote_infarct | F2: 398 | G2: 196 | I2: 52 | J2: Benchmark v2 | K2: ct | L2: auc | M2: 0.624 | N2: 0.61 | O2: 0.59 | P2: ct_fm | Q2: 0.637
A3: cq500 | B3: CQ500 (qure.ai) | C3: CT | D3: multilabel | E3: ICH, IPH, IVH, SDH, SAH, CalvarialFracture, MassEffect, MidlineShift | F3: 471 | G3: 210 | I3: 71 | J3: Benchmark v2 | K3: ct | L3: auc_ovr_macro | M3: 0.838 | N3: 0.849 | O3: 0.694 | P3: ct_fm_triage | Q3: 0.712 | R3: Chilamkurthy 2018 (qure.ai); CT-FM | S3: Six findings: ICH, IPH, IVH, SDH, SAH, calvarial fracture. Cross-validated.
A4: cq500_bleed_side | B4: CQ500 (qure.ai) | C4: CT | D4: binary | E4: left | F4: 132 | G4: 68 | I4: 19 | J4: Benchmark v2 | K4: ct | L4: auc | M4: 0.873 | N4: 0.824 | O4: 0.612 | P4: ct_fm | Q4: 0.716
A5: cq500_edh | B5: CQ500 (qure.ai) | C5: CT | D5: binary | E5: EDH | F5: 471 | G5: 13 | I5: 71 | J5: Benchmark v2 | K5: ct | L5: auc | M5: 0.753 | N5: 0.611 | O5: 0.625 | P5: ct_fm_triage | Q5: 0.637
A6: cq500_other_fracture | B6: CQ500 (qure.ai) | C6: CT | D6: binary | E6: OtherFracture | F6: 471 | G6: 12 | I6: 71 | J6: Benchmark v2 | K6: ct | L6: auc | M6: 0.779 | N6: 0.803 | O6: 0.713 | P6: ct_fm_triage | Q6: 0.65
A7: isles24_lvo_side | B7: ISLES 2024 (NCCT / CTA / CTP) | C7: CT | D7: binary | E7: left | F7: 137 | G7: 75 | I7: 19 | J7: Benchmark v2 | K7: stroke | L7: auc | M7: 0.948 | N7: 0.933 | O7: 0.893 | P7: ct_fm | Q7: 0.655 | R7: ISLES'24
A8: isles24_mrs | B8: ISLES 2024 (NCCT / CTA / CTP) | C8: CT | D8: binary | E8: poor_outcome | F8: 129 | G8: 44 | I8: 17 | J8: Benchmark v2 | K8: stroke | L8: auc | M8: 0.693 | N8: 0.702 | O8: 0.703 | P8: ct_fm_triage | Q8: 0.697
A9: isles24_mrs_discharge | B9: ISLES 2024 (NCCT / CTA / CTP) | C9: CT | D9: binary | E9: poor_outcome | F9: 97 | G9: 43 | I9: 15 | J9: Benchmark v2 | K9: stroke | L9: auc | M9: 0.66 | N9: 0.634 | O9: 0.651 | P9: ct_fm_triage | Q9: 0.717
A10: rsna_ich | B10: RSNA Intracranial Hemorrhage 2019 | C10: CT | D10: multilabel | E10: any, epidural, intraparenchymal, intraventricular, subarachnoid, subdural | F10: 3500 | G10: 1407 | I10: 1000 | J10: Benchmark v2 | K10: ct | L10: auc_ovr_macro | N10: 0.867 | O10: 0.764 | P10: ct_fm | Q10: 0.818 | R10: RSNA 2019 Kaggle | S10: Seen by BQ multitask models (hemorrhage labels trained).
A11: abide_asd | B11: ABIDE I | C11: MRI | D11: binary | E11: ASD | F11: 1034 | G11: 504 | I11: 151 | J11: Benchmark v2 | K11: neuro_psych | L11: auc | M11: 0.613 | N11: 0.566 | O11: 0.596 | P11: brainiac | Q11: 0.604 | R11: BrainDINO | S11: Seen for runs that train autism_severity (seen map).
A12: atlas | B12: ATLAS v2.0 (chronic stroke T1) | C12: MRI | D12: segmentation | J12: Benchmark v2 (seg) | K12: segmentation | L12: Dice | S12: Chronic stroke lesion (T1).
A13: atlas_days_post_stroke | B13: ATLAS v2.0 (chronic stroke T1) | C13: MRI | D13: regression | E13: log_days | F13: 1109 | H13: 0 to 9 | I13: 165 | J13: Benchmark v2 | K13: stroke | L13: r2 | M13: 0.365 | N13: 0.345 | O13: 0.271 | P13: brainiac | Q13: 0.088 | R13: BrainIAC; BrainDINO | S13: BrainIAC / BrainDINO also report this (MAE in days).
A14: atlas_lesion_volume | B14: ATLAS v2.0 (chronic stroke T1) | C14: MRI | D14: regression | E14: log_lesion_ml | F14: 1448 | H14: 0 to 6 | I14: 217 | J14: Benchmark v2 | K14: stroke | L14: r2 | M14: 0.737 | N14: 0.724 | O14: 0.614 | P14: brainiac | Q14: 0.141
A15: brats2023_gli | B15: BraTS glioma (2021 / 2023 / 2024 GLI) | C15: MRI | D15: segmentation | J15: Benchmark v2 (seg) | K15: segmentation | L15: Dice | R15: BrainDINO (BraTS2021) | S15: Glioma WT / TC / ET.
A16: brats2023_men | B16: BraTS-MEN 2023 | C16: MRI | D16: segmentation | J16: Benchmark v2 (seg) | K16: segmentation | L16: Dice | R16: BrainDINO | S16: Meningioma.
A17: ixi_age | B17: IXI | C17: MRI | D17: regression | E17: Age | F17: 561 | H17: 20 to 86 | I17: 85 | J17: Benchmark v2 | K17: age | L17: r2 | M17: 0.864 | N17: 0.805 | O17: 0.723 | P17: brainiac | Q17: 0.673 | R17: BrainDINO; BrainIAC
A18: ms3seg_age | B18: MS3SEG | C18: MRI | D18: regression | E18: Age | F18: 100 | H18: 18 to 55 | I18: 15 | J18: Benchmark v2 | K18: age | L18: r2 | M18: 0.374 | N18: 0.272 | O18: 0.285 | P18: brainiac | Q18: 0.285
A19: ms3seg_lesion_load | B19: MS3SEG | C19: MRI | D19: regression | E19: log_lesion_ml | F19: 100 | H19: 0 to 4 | I19: 15 | J19: Benchmark v2 | K19: lesion_tumor | L19: r2 | M19: 0.714 | N19: 0.654 | O19: 0.37 | P19: brainiac | Q19: 0.647
A20: msd | B20: MSD Task01 BrainTumour (non-BraTS remainder) | C20: MRI | D20: binary | E20: enhancing_high | F20: 115 | G20: 25 | I20: 16 | J20: Benchmark v2 | K20: lesion_tumor | L20: auc | M20: 0.742 | N20: 0.711 | O20: 0.631 | P20: brainiac | Q20: 0.629
A21: oasis1_cdr | B21: OASIS-1 | C21: MRI | D21: binary | E21: CDR>0 | F21: 235 | G21: 100 | I21: 39 | J21: Benchmark v2 | K21: neuro_psych | L21: auc | M21: 0.872 | N21: 0.826 | O21: 0.714 | P21: brainiac | Q21: 0.583 | R21: BrainIAC; BrainDINO | S21: Matches BrainIAC MCI and BrainDINO dementia cohort (235 subjects).
A22: oasis1_mmse | B22: OASIS-1 | C22: MRI | D22: regression | E22: MMSE | F22: 235 | H22: 14 to 30 | I22: 39 | J22: Benchmark v2 | K22: neuro_psych | L22: r2 | M22: 0.317 | N22: 0.209 | O22: 0.032 | P22: brainiac | Q22: 0.209 | S22: Seen for runs that train mmse.
A23: oasis2_cdr | B23: OASIS-2 (longitudinal) | C23: MRI | D23: binary | E23: CDR>0 | F23: 373 | G23: 167 | I23: 140 | J23: Benchmark v2 | K23: neuro_psych | L23: auc | M23: 0.679 | N23: 0.687 | O23: 0.602 | P23: brainiac | Q23: 0.665 | S23: Seen for runs that train mmse.
A24: oasis2_mmse | B24: OASIS-2 (longitudinal) | C24: MRI | D24: regression | E24: MMSE | F24: 371 | H24: 4 to 30 | I24: 140 | J24: Benchmark v2 | K24: neuro_psych | L24: r2 | M24: 0.017 | N24: 0.036 | O24: 0.104 | P24: brainiac | Q24: -0.045 | S24: Seen for runs that train mmse.
A25: pixar_age | B25: Pixar (OpenNeuro ds000228) | C25: MRI | D25: regression | E25: Age | F25: 155 | H25: 4 to 39 | I25: 23 | J25: Benchmark v2 | K25: age | L25: r2 | M25: 0.897 | N25: 0.779 | O25: 0.815 | P25: brainiac | Q25: 0.805 | R25: BrainDINO
A26: valdo_epvs | B26: VALDO 2021 (small vessel disease) | C26: MRI | D26: regression | E26: log1p_EPVS | F26: 40 | H26: 2 to 5 | I26: 5 | J26: Benchmark v2 | K26: lesion_tumor | L26: r2 | M26: 0.202 | N26: 0.181 | O26: 0.183 | P26: brainiac | Q26: 0.113
A27: wmh | B27: WMH Segmentation Challenge 2017 | C27: MRI | D27: segmentation | J27: Benchmark v2 (seg) | K27: segmentation | L27: Dice | R27: WMH challenge | S27: White matter hyperintensities.
A28: aisd | B28: AISD (acute ischemic stroke, NCCT) | C28: CT | D28: segmentation | J28: Suite only | L28: Dice | S28: Hypodense infarct on NCCT; tests density sensitivity. Candidate CT segmentation task.
A29: cq500_chronic_bleed | B29: CQ500 (qure.ai) | C29: CT | D29: binary | E29: ChronicBleed | F29: 471 | G29: 19 | I29: 71 | J29: Suite only: Interval too wide (too few scans / positives) | S29: Diagnostic for the CT contrast fix (chronic SDH is hypodense); run outside the leaderboard.
A30: instance | B30: INSTANCE 2022 (ICH segmentation) | C30: CT | D30: segmentation | J30: Suite only | L30: Dice | S30: ICH masks; trained by hemorrhage_segmentation: seen for BQ.
A31: isles24 | B31: ISLES 2024 (NCCT / CTA / CTP) | C31: CT | D31: segmentation | J31: Suite only | L31: Dice | S31: CT stroke lesion. Candidate: no CT segmentation in the benchmark yet.
A32: isles24_cow | B32: ISLES 2024 (NCCT / CTA / CTP) | C32: CT | D32: segmentation | J32: Suite only | L32: Dice | S32: Circle of Willis vessels on CTA.
A33: isles24_nihss | B33: ISLES 2024 (NCCT / CTA / CTP) | C33: CT | D33: regression | E33: NIHSS | F33: 145 | H33: 0 to 24 | I33: 21 | J33: Suite only: No model above 0.15 skill
A34: isles24_nihss_discharge | B34: ISLES 2024 (NCCT / CTA / CTP) | C34: CT | D34: regression | E34: NIHSS | F34: 97 | H34: 0 to 42 | I34: 15 | J34: Suite only: No model above 0.15 skill
A35: seg_cq500 | B35: CQ500 (qure.ai) | C35: CT | D35: segmentation | J35: Suite only | L35: Dice | S35: CQ500 bleed masks; trained by hemorrhage_segmentation: seen for BQ.
A36: abide_ados | B36: ABIDE I | C36: MRI | D36: regression | E36: ADOS_severity | F36: 235 | H36: 1 to 10 | I36: 41 | J36: Suite only: No model above 0.15 skill
A37: atlas_lesion_side | B37: ATLAS v2.0 (chronic stroke T1) | C37: MRI | D37: binary | E37: left | F37: 1131 | G37: 556 | I37: 168 | J37: Suite only: Saturated (AUC 0.97-0.98 for most models)
A38: brats2023_ped | B38: BraTS-PED 2023 | C38: MRI | D38: segmentation | J38: Suite only | L38: Dice | S38: Paediatric tumours.
A39: brats2024_gli | B39: BraTS glioma (2021 / 2023 / 2024 GLI) | C39: MRI | D39: segmentation | J39: Suite only | L39: Dice | S39: Post-treatment glioma incl. resection cavity.
A40: gli_idh | B40: BraTS glioma (2021 / 2023 / 2024 GLI) | C40: MRI | D40: binary | E40: IDH_mutant | F40: 73 | G40: 53 | I40: 9 | J40: Suite only: Interval too wide (too few scans / positives) | S40: TCGA subset; replace with UCSF-PDGM (BrainDINO: 360/92).
...

Sheet Training labels
A1: Registry task | B1: Type | C1: Group | D1: Role | E1: Datasets (train-split labelled volumes) | F1: Train-split labelled volumes | G1: Eval-only label rows | H1: Description
A2: age | B2: regression | D2: trained | E2: Yale brain metastases (FOMO) (25,058), Healthy Brain Network (FOMO) (5,383), NKI-Rockland (FOMO) (3,413), CoRR (FOMO) (2,001), Infant MRI (FOMO) (1,249), SLIM longitudinal (FOMO) (759), WAND (FOMO) (597), BrainLat (FOMO) (413), FOMO cohort: nigerian (203), Cuban Human Brain Mapping (FOMO) (153), FOMO cohort: hbnssi (137), FOMO cohort: wayne (134), FOMO cohort: abd (131), ACPI (FOMO) (122), FOMO cohort: ageility (98), FOMO cohort: yale_highres (93), FOMO cohort: cunmet (45), Tao Wu Parkinson's (FOMO) (30), FOMO cohort: cleveland (23) | F2: 40042 | G2: 1097 | H2: Estimate the age of the person in years from this brain scan.
A3: brain_asymmetry | B3: regression | D3: trained | E3: Yale brain metastases (FOMO) (24,037), RSNA Intracranial Hemorrhage 2019 (12,384), BraTS glioma (2021 / 2023 / 2024 GLI) (6,233), Healthy Brain Network (FOMO) (4,797), NKI-Rockland (FOMO) (4,364), BraTS-MEN 2023 (2,749), CoRR (FOMO) (2,002), BraTS-GoAT 2024 (1,108), IXI (869), ABIDE I (819), SLIM longitudinal (FOMO) (700), AOMIC ID1000 (696), WAND (FOMO) (492), BrainLat (FOMO) (452), M4Raw low-field (FOMO) (442), FOMO cohort: wayne (424), BraTS-PED 2023 (408), OASIS-1 (314), HemSeg-500 (280), FOMO cohort: yale_highres (195), FOMO cohort: nigerian (176), OASIS-2 (longitudinal) (176), AOMIC PIOP2 (169), AOMIC PIOP1 (162), FOMO cohort: abd (124), Pixar (OpenNeuro ds000228) (115), Cuban Human Brain Mapping (FOMO) (114), FOMO cohort: beijing (107), ACPI (FOMO) (98), FOMO cohort: ageility (98), FOMO cohort: hbnssi (87), BHSD (brain hemorrhage segmentation) (84), Infant MRI (FOMO) (68), MICA-MICs (FOMO) (36), FOMO cohort: cunmet (35), Tao Wu Parkinson's (FOMO) (29), FOMO cohort: cleveland (23) | F3: 65466 | G3: 0 | H3: How asymmetric is the brain outline between the left and right hemispheres?
A4: brain_mask | B4: segmentation | D4: trained | E4: RSNA Intracranial Hemorrhage 2019 (17,679), Healthy Brain Network (FOMO) (5,108), NKI-Rockland (FOMO) (4,425), CoRR (FOMO) (2,008), IXI (869), ABIDE I (823), SLIM longitudinal (FOMO) (769), AOMIC ID1000 (696), WAND (FOMO) (529), M4Raw low-field (FOMO) (468), BrainLat (FOMO) (455), FOMO cohort: wayne (444), Infant MRI (FOMO) (428), HemSeg-500 (382), OASIS-1 (315), FOMO cohort: yale_highres (196), FOMO cohort: nigerian (195), OASIS-2 (longitudinal) (176), AOMIC PIOP2 (169), AOMIC PIOP1 (162), Cuban Human Brain Mapping (FOMO) (142), FOMO cohort: beijing (134), BHSD (brain hemorrhage segmentation) (132), FOMO cohort: hbnssi (126), FOMO cohort: abd (125), Pixar (OpenNeuro ds000228) (115), ACPI (FOMO) (102), FOMO cohort: ageility (98), AHEAD 7T (FOMO) (79), FOMO cohort: cunmet (38), MICA-MICs (FOMO) (37), Tao Wu Parkinson's (FOMO) (30), FOMO cohort: cleveland (23) | F4: 37477 | G4: 0 | H4: Segment the brain (skull stripping).
A5: brain_volume | B5: regression | D5: trained | E5: Yale brain metastases (FOMO) (24,037), RSNA Intracranial Hemorrhage 2019 (12,384), BraTS glioma (2021 / 2023 / 2024 GLI) (6,233), Healthy Brain Network (FOMO) (4,797), NKI-Rockland (FOMO) (4,364), BraTS-MEN 2023 (2,749), CoRR (FOMO) (2,002), BraTS-GoAT 2024 (1,108), IXI (869), ABIDE I (819), SLIM longitudinal (FOMO) (700), AOMIC ID1000 (696), WAND (FOMO) (492), BrainLat (FOMO) (452), M4Raw low-field (FOMO) (442), FOMO cohort: wayne (424), BraTS-PED 2023 (408), OASIS-1 (314), HemSeg-500 (280), FOMO cohort: yale_highres (195), FOMO cohort: nigerian (176), OASIS-2 (longitudinal) (176), AOMIC PIOP2 (169), AOMIC PIOP1 (162), FOMO cohort: abd (124), Pixar (OpenNeuro ds000228) (115), Cuban Human Brain Mapping (FOMO) (114), FOMO cohort: beijing (107), ACPI (FOMO) (98), FOMO cohort: ageility (98), FOMO cohort: hbnssi (87), BHSD (brain hemorrhage segmentation) (84), Infant MRI (FOMO) (68), MICA-MICs (FOMO) (36), FOMO cohort: cunmet (35), Tao Wu Parkinson's (FOMO) (29), FOMO cohort: cleveland (23) | F5: 65466 | G5: 0 | H5: Estimate the brain volume after normalisation to a standard head size.
A6: cq500_fracture | B6: binary | D6: held_out | F6: 0 | G6: 515 | H6: Is there a fracture of the skull vault?
A7: cq500_hemorrhage | B7: binary | D7: held_out | F7: 0 | G7: 515 | H7: Does this head CT show intracranial bleeding?
A8: cq500_intraparenchymal | B8: binary | D8: held_out | F8: 0 | G8: 515 | H8: Is there bleeding in the brain parenchyma?
A9: cq500_mass_effect | B9: binary | D9: held_out | F9: 0 | G9: 515 | H9: Is there mass effect compressing brain structures?
A10: cq500_midline_shift | B10: binary | D10: held_out | F10: 0 | G10: 515 | H10: Is there a shift of the midline structures?
A11: cq500_subdural | B11: binary | D11: held_out | F11: 0 | G11: 515 | H11: Is there a subdural hemorrhage?
A12: ct_brain_density | B12: regression | D12: trained | E12: RSNA Intracranial Hemorrhage 2019 (17,679), HemSeg-500 (382), BHSD (brain hemorrhage segmentation) (132) | F12: 18193 | G12: 0 | H12: Estimate the mean attenuation of brain tissue in Hounsfield units.
A13: ct_calcification | B13: regression | D13: trained | E13: RSNA Intracranial Hemorrhage 2019 (17,679), HemSeg-500 (382), BHSD (brain hemorrhage segmentation) (132) | F13: 18193 | G13: 0 | H13: Estimate the burden of intracranial calcification on this head CT.
A14: ct_csf_fraction | B14: regression | D14: trained | E14: RSNA Intracranial Hemorrhage 2019 (17,679), HemSeg-500 (382), BHSD (brain hemorrhage segmentation) (132) | F14: 18193 | G14: 0 | H14: Estimate the fraction of the intracranial space occupied by cerebrospinal fluid on CT.
A15: ct_skull_density | B15: regression | D15: trained | E15: RSNA Intracranial Hemorrhage 2019 (17,679), HemSeg-500 (382), BHSD (brain hemorrhage segmentation) (132) | F15: 18193 | G15: 0 | H15: Estimate the density of the skull bone in Hounsfield units.
A16: dementia | B16: binary | D16: held_out | F16: 0 | G16: 426 | H16: Does this person have dementia?
A17: enhancing_tumor | B17: segmentation | D17: trained | E17: BraTS glioma (2021 / 2023 / 2024 GLI) (6,480), BraTS-MEN 2023 (2,868) | F17: 9348 | G17: 0 | H17: Segment the contrast-enhancing tumor.
A18: hemorrhage_any | B18: binary | D18: trained | E18: RSNA Intracranial Hemorrhage 2019 (17,045) | F18: 17045 | G18: 0 | H18: Is there any intracranial hemorrhage on this head CT?
A19: hemorrhage_epidural | B19: binary | D19: trained | E19: RSNA Intracranial Hemorrhage 2019 (17,045) | F19: 17045 | G19: 0 | H19: Is there an epidural hematoma?
A20: hemorrhage_intraparenchymal | B20: binary | D20: trained | E20: RSNA Intracranial Hemorrhage 2019 (17,045) | F20: 17045 | G20: 0 | H20: Is there an intraparenchymal hemorrhage?
A21: hemorrhage_intraventricular | B21: binary | D21: trained | E21: RSNA Intracranial Hemorrhage 2019 (17,045) | F21: 17045 | G21: 0 | H21: Is there intraventricular hemorrhage?
A22: hemorrhage_subarachnoid | B22: binary | D22: trained | E22: RSNA Intracranial Hemorrhage 2019 (17,045) | F22: 17045 | G22: 0 | H22: Is there subarachnoid hemorrhage?
A23: hemorrhage_subdural | B23: binary | D23: trained | E23: RSNA Intracranial Hemorrhage 2019 (17,045) | F23: 17045 | G23: 0 | H23: Is there a subdural hematoma?
A24: intensity_asymmetry | B24: regression | D24: trained | E24: Yale brain metastases (FOMO) (24,037), RSNA Intracranial Hemorrhage 2019 (12,384), BraTS glioma (2021 / 2023 / 2024 GLI) (6,233), Healthy Brain Network (FOMO) (4,797), NKI-Rockland (FOMO) (4,364), BraTS-MEN 2023 (2,749), CoRR (FOMO) (2,002), BraTS-GoAT 2024 (1,108), IXI (869), ABIDE I (819), SLIM longitudinal (FOMO) (700), AOMIC ID1000 (696), WAND (FOMO) (492), BrainLat (FOMO) (452), M4Raw low-field (FOMO) (442), FOMO cohort: wayne (424), BraTS-PED 2023 (408), OASIS-1 (314), HemSeg-500 (280), FOMO cohort: yale_highres (195), FOMO cohort: nigerian (176), OASIS-2 (longitudinal) (176), AOMIC PIOP2 (169), AOMIC PIOP1 (162), FOMO cohort: abd (124), Pixar (OpenNeuro ds000228) (115), Cuban Human Brain Mapping (FOMO) (114), FOMO cohort: beijing (107), ACPI (FOMO) (98), FOMO cohort: ageility (98), FOMO cohort: hbnssi (87), BHSD (brain hemorrhage segmentation) (84), Infant MRI (FOMO) (68), MICA-MICs (FOMO) (36), FOMO cohort: cunmet (35), Tao Wu Parkinson's (FOMO) (29), FOMO cohort: cleveland (23) | F24: 65466 | G24: 0 | H24: How different are the left and right hemispheres in signal intensity?
A25: ms_lesions | B25: segmentation | D25: held_out | F25: 0 | G25: 100 | H25: Segment the multiple sclerosis lesions.
A26: neuro_diagnosis | B26: multiclass | D26: trained | E26: BrainLat (FOMO) (418) | F26: 418 | G26: 0 | H26: Which neurological diagnosis best fits this brain MRI?
A27: resection_cavity | B27: segmentation | D27: trained | E27: BraTS glioma (2021 / 2023 / 2024 GLI) (2,972) | F27: 2972 | G27: 0 | H27: Segment the surgical resection cavity.
A28: seg_amygdala | B28: segmentation | D28: trained | E28: Yale brain metastases (FOMO) (3,111), NKI-Rockland (FOMO) (3,074), BraTS glioma (2021 / 2023 / 2024 GLI) (2,736), Healthy Brain Network (FOMO) (2,575), BraTS-MEN 2023 (2,149), RSNA Intracranial Hemorrhage 2019 (1,708), CoRR (FOMO) (1,595), SLIM longitudinal (FOMO) (771), IXI (692), Infant MRI (FOMO) (691), ABIDE I (640), AOMIC ID1000 (558), WAND (FOMO) (495), FOMO cohort: wayne (449), BraTS-GoAT 2024 (419), BrainLat (FOMO) (358), M4Raw low-field (FOMO) (347), BraTS-PED 2023 (325), OASIS-1 (246), FOMO cohort: yale_highres (198), Cuban Human Brain Mapping (FOMO) (153), FOMO cohort: nigerian (139), OASIS-2 (longitudinal) (138), FOMO cohort: hbnssi (137), FOMO cohort: beijing (135), FOMO cohort: abd (131), AOMIC PIOP2 (125), AOMIC PIOP1 (117), ACPI (FOMO) (102), FOMO cohort: ageility (98), Pixar (OpenNeuro ds000228) (87), AHEAD 7T (FOMO) (79), FOMO cohort: cunmet (45), MICA-MICs (FOMO) (37), Tao Wu Parkinson's (FOMO) (30), FOMO cohort: cleveland (23) | F28: 24713 | G28: 0 | H28: Segment both amygdalae.
A29: seg_brainstem | B29: segmentation | D29: trained | E29: Yale brain metastases (FOMO) (3,111), NKI-Rockland (FOMO) (3,074), BraTS glioma (2021 / 2023 / 2024 GLI) (2,736), Healthy Brain Network (FOMO) (2,575), BraTS-MEN 2023 (2,149), RSNA Intracranial Hemorrhage 2019 (1,708), CoRR (FOMO) (1,595), SLIM longitudinal (FOMO) (771), IXI (692), Infant MRI (FOMO) (691), ABIDE I (640), AOMIC ID1000 (558), WAND (FOMO) (495), FOMO cohort: wayne (449), BraTS-GoAT 2024 (419), BrainLat (FOMO) (358), M4Raw low-field (FOMO) (347), BraTS-PED 2023 (325), OASIS-1 (246), FOMO cohort: yale_highres (198), Cuban Human Brain Mapping (FOMO) (153), FOMO cohort: nigerian (139), OASIS-2 (longitudinal) (138), FOMO cohort: hbnssi (137), FOMO cohort: beijing (135), FOMO cohort: abd (131), AOMIC PIOP2 (125), AOMIC PIOP1 (117), ACPI (FOMO) (102), FOMO cohort: ageility (98), Pixar (OpenNeuro ds000228) (87), AHEAD 7T (FOMO) (79), FOMO cohort: cunmet (45), MICA-MICs (FOMO) (37), Tao Wu Parkinson's (FOMO) (30), FOMO cohort: cleveland (23) | F29: 24713 | G29: 0 | H29: Segment the brainstem.
A30: seg_caudate | B30: segmentation | D30: trained | E30: Yale brain metastases (FOMO) (3,111), NKI-Rockland (FOMO) (3,074), BraTS glioma (2021 / 2023 / 2024 GLI) (2,736), Healthy Brain Network (FOMO) (2,575), BraTS-MEN 2023 (2,149), RSNA Intracranial Hemorrhage 2019 (1,708), CoRR (FOMO) (1,595), SLIM longitudinal (FOMO) (771), IXI (692), Infant MRI (FOMO) (691), ABIDE I (640), AOMIC ID1000 (558), WAND (FOMO) (495), FOMO cohort: wayne (449), BraTS-GoAT 2024 (419), BrainLat (FOMO) (358), M4Raw low-field (FOMO) (347), BraTS-PED 2023 (325), OASIS-1 (246), FOMO cohort: yale_highres (198), Cuban Human Brain Mapping (FOMO) (153), FOMO cohort: nigerian (139), OASIS-2 (longitudinal) (138), FOMO cohort: hbnssi (137), FOMO cohort: beijing (135), FOMO cohort: abd (131), AOMIC PIOP2 (125), AOMIC PIOP1 (117), ACPI (FOMO) (102), FOMO cohort: ageility (98), Pixar (OpenNeuro ds000228) (87), AHEAD 7T (FOMO) (79), FOMO cohort: cunmet (45), MICA-MICs (FOMO) (37), Tao Wu Parkinson's (FOMO) (30), FOMO cohort: cleveland (23) | F30: 24713 | G30: 0 | H30: Segment the caudate nuclei.
A31: seg_cerebellum | B31: segmentation | D31: trained | E31: Yale brain metastases (FOMO) (3,111), NKI-Rockland (FOMO) (3,074), BraTS glioma (2021 / 2023 / 2024 GLI) (2,736), Healthy Brain Network (FOMO) (2,575), BraTS-MEN 2023 (2,149), RSNA Intracranial Hemorrhage 2019 (1,708), CoRR (FOMO) (1,595), SLIM longitudinal (FOMO) (771), IXI (692), Infant MRI (FOMO) (691), ABIDE I (640), AOMIC ID1000 (558), WAND (FOMO) (495), FOMO cohort: wayne (449), BraTS-GoAT 2024 (419), BrainLat (FOMO) (358), M4Raw low-field (FOMO) (347), BraTS-PED 2023 (325), OASIS-1 (246), FOMO cohort: yale_highres (198), Cuban Human Brain Mapping (FOMO) (153), FOMO cohort: nigerian (139), OASIS-2 (longitudinal) (138), FOMO cohort: hbnssi (137), FOMO cohort: beijing (135), FOMO cohort: abd (131), AOMIC PIOP2 (125), AOMIC PIOP1 (117), ACPI (FOMO) (102), FOMO cohort: ageility (98), Pixar (OpenNeuro ds000228) (87), AHEAD 7T (FOMO) (79), FOMO cohort: cunmet (45), MICA-MICs (FOMO) (37), Tao Wu Parkinson's (FOMO) (30), FOMO cohort: cleveland (23) | F31: 24713 | G31: 0 | H31: Segment the cerebellum.
A32: seg_cortex | B32: segmentation | D32: trained | E32: Yale brain metastases (FOMO) (3,111), NKI-Rockland (FOMO) (3,074), BraTS glioma (2021 / 2023 / 2024 GLI) (2,736), Healthy Brain Network (FOMO) (2,575), BraTS-MEN 2023 (2,149), RSNA Intracranial Hemorrhage 2019 (1,708), CoRR (FOMO) (1,595), SLIM longitudinal (FOMO) (771), IXI (692), Infant MRI (FOMO) (691), ABIDE I (640), AOMIC ID1000 (558), WAND (FOMO) (495), FOMO cohort: wayne (449), BraTS-GoAT 2024 (419), BrainLat (FOMO) (358), M4Raw low-field (FOMO) (347), BraTS-PED 2023 (325), OASIS-1 (246), FOMO cohort: yale_highres (198), Cuban Human Brain Mapping (FOMO) (153), FOMO cohort: nigerian (139), OASIS-2 (longitudinal) (138), FOMO cohort: hbnssi (137), FOMO cohort: beijing (135), FOMO cohort: abd (131), AOMIC PIOP2 (125), AOMIC PIOP1 (117), ACPI (FOMO) (102), FOMO cohort: ageility (98), Pixar (OpenNeuro ds000228) (87), AHEAD 7T (FOMO) (79), FOMO cohort: cunmet (45), MICA-MICs (FOMO) (37), Tao Wu Parkinson's (FOMO) (30), FOMO cohort: cleveland (23) | F32: 24713 | G32: 0 | H32: Segment the cerebral cortex (grey matter).
A33: seg_csf | B33: segmentation | D33: trained | E33: Yale brain metastases (FOMO) (3,111), NKI-Rockland (FOMO) (3,074), BraTS glioma (2021 / 2023 / 2024 GLI) (2,736), Healthy Brain Network (FOMO) (2,575), BraTS-MEN 2023 (2,149), RSNA Intracranial Hemorrhage 2019 (1,708), CoRR (FOMO) (1,595), SLIM longitudinal (FOMO) (771), IXI (692), Infant MRI (FOMO) (691), ABIDE I (640), AOMIC ID1000 (558), WAND (FOMO) (495), FOMO cohort: wayne (449), BraTS-GoAT 2024 (419), BrainLat (FOMO) (358), M4Raw low-field (FOMO) (347), BraTS-PED 2023 (325), OASIS-1 (246), FOMO cohort: yale_highres (198), Cuban Human Brain Mapping (FOMO) (153), FOMO cohort: nigerian (139), OASIS-2 (longitudinal) (138), FOMO cohort: hbnssi (137), FOMO cohort: beijing (135), FOMO cohort: abd (131), AOMIC PIOP2 (125), AOMIC PIOP1 (117), ACPI (FOMO) (102), FOMO cohort: ageility (98), Pixar (OpenNeuro ds000228) (87), AHEAD 7T (FOMO) (79), FOMO cohort: cunmet (45), MICA-MICs (FOMO) (37), Tao Wu Parkinson's (FOMO) (30), FOMO cohort: cleveland (23) | F33: 24713 | G33: 0 | H33: Segment the extraventricular cerebrospinal fluid.
A34: seg_hippocampus | B34: segmentation | D34: trained | E34: Yale brain metastases (FOMO) (3,111), NKI-Rockland (FOMO) (3,074), BraTS glioma (2021 / 2023 / 2024 GLI) (2,736), Healthy Brain Network (FOMO) (2,575), BraTS-MEN 2023 (2,149), RSNA Intracranial Hemorrhage 2019 (1,708), CoRR (FOMO) (1,595), SLIM longitudinal (FOMO) (771), IXI (692), Infant MRI (FOMO) (691), ABIDE I (640), AOMIC ID1000 (558), WAND (FOMO) (495), FOMO cohort: wayne (449), BraTS-GoAT 2024 (419), BrainLat (FOMO) (358), M4Raw low-field (FOMO) (347), BraTS-PED 2023 (325), OASIS-1 (246), FOMO cohort: yale_highres (198), Cuban Human Brain Mapping (FOMO) (153), FOMO cohort: nigerian (139), OASIS-2 (longitudinal) (138), FOMO cohort: hbnssi (137), FOMO cohort: beijing (135), FOMO cohort: abd (131), AOMIC PIOP2 (125), AOMIC PIOP1 (117), ACPI (FOMO) (102), FOMO cohort: ageility (98), Pixar (OpenNeuro ds000228) (87), AHEAD 7T (FOMO) (79), FOMO cohort: cunmet (45), MICA-MICs (FOMO) (37), Tao Wu Parkinson's (FOMO) (30), FOMO cohort: cleveland (23) | F34: 24713 | G34: 0 | H34: Segment both hippocampi.
A35: seg_pallidum | B35: segmentation | D35: trained | E35: Yale brain metastases (FOMO) (3,111), NKI-Rockland (FOMO) (3,074), BraTS glioma (2021 / 2023 / 2024 GLI) (2,736), Healthy Brain Network (FOMO) (2,575), BraTS-MEN 2023 (2,149), RSNA Intracranial Hemorrhage 2019 (1,708), CoRR (FOMO) (1,595), SLIM longitudinal (FOMO) (771), IXI (692), Infant MRI (FOMO) (691), ABIDE I (640), AOMIC ID1000 (558), WAND (FOMO) (495), FOMO cohort: wayne (449), BraTS-GoAT 2024 (419), BrainLat (FOMO) (358), M4Raw low-field (FOMO) (347), BraTS-PED 2023 (325), OASIS-1 (246), FOMO cohort: yale_highres (198), Cuban Human Brain Mapping (FOMO) (153), FOMO cohort: nigerian (139), OASIS-2 (longitudinal) (138), FOMO cohort: hbnssi (137), FOMO cohort: beijing (135), FOMO cohort: abd (131), AOMIC PIOP2 (125), AOMIC PIOP1 (117), ACPI (FOMO) (102), FOMO cohort: ageility (98), Pixar (OpenNeuro ds000228) (87), AHEAD 7T (FOMO) (79), FOMO cohort: cunmet (45), MICA-MICs (FOMO) (37), Tao Wu Parkinson's (FOMO) (30), FOMO cohort: cleveland (23) | F35: 24713 | G35: 0 | H35: Segment the globus pallidus on both sides.
A36: seg_putamen | B36: segmentation | D36: trained | E36: Yale brain metastases (FOMO) (3,111), NKI-Rockland (FOMO) (3,074), BraTS glioma (2021 / 2023 / 2024 GLI) (2,736), Healthy Brain Network (FOMO) (2,575), BraTS-MEN 2023 (2,149), RSNA Intracranial Hemorrhage 2019 (1,708), CoRR (FOMO) (1,595), SLIM longitudinal (FOMO) (771), IXI (692), Infant MRI (FOMO) (691), ABIDE I (640), AOMIC ID1000 (558), WAND (FOMO) (495), FOMO cohort: wayne (449), BraTS-GoAT 2024 (419), BrainLat (FOMO) (358), M4Raw low-field (FOMO) (347), BraTS-PED 2023 (325), OASIS-1 (246), FOMO cohort: yale_highres (198), Cuban Human Brain Mapping (FOMO) (153), FOMO cohort: nigerian (139), OASIS-2 (longitudinal) (138), FOMO cohort: hbnssi (137), FOMO cohort: beijing (135), FOMO cohort: abd (131), AOMIC PIOP2 (125), AOMIC PIOP1 (117), ACPI (FOMO) (102), FOMO cohort: ageility (98), Pixar (OpenNeuro ds000228) (87), AHEAD 7T (FOMO) (79), FOMO cohort: cunmet (45), MICA-MICs (FOMO) (37), Tao Wu Parkinson's (FOMO) (30), FOMO cohort: cleveland (23) | F36: 24713 | G36: 0 | H36: Segment the putamen on both sides.
A37: seg_thalamus | B37: segmentation | D37: trained | E37: Yale brain metastases (FOMO) (3,111), NKI-Rockland (FOMO) (3,074), BraTS glioma (2021 / 2023 / 2024 GLI) (2,736), Healthy Brain Network (FOMO) (2,575), BraTS-MEN 2023 (2,149), RSNA Intracranial Hemorrhage 2019 (1,708), CoRR (FOMO) (1,595), SLIM longitudinal (FOMO) (771), IXI (692), Infant MRI (FOMO) (691), ABIDE I (640), AOMIC ID1000 (558), WAND (FOMO) (495), FOMO cohort: wayne (449), BraTS-GoAT 2024 (419), BrainLat (FOMO) (358), M4Raw low-field (FOMO) (347), BraTS-PED 2023 (325), OASIS-1 (246), FOMO cohort: yale_highres (198), Cuban Human Brain Mapping (FOMO) (153), FOMO cohort: nigerian (139), OASIS-2 (longitudinal) (138), FOMO cohort: hbnssi (137), FOMO cohort: beijing (135), FOMO cohort: abd (131), AOMIC PIOP2 (125), AOMIC PIOP1 (117), ACPI (FOMO) (102), FOMO cohort: ageility (98), Pixar (OpenNeuro ds000228) (87), AHEAD 7T (FOMO) (79), FOMO cohort: cunmet (45), MICA-MICs (FOMO) (37), Tao Wu Parkinson's (FOMO) (30), FOMO cohort: cleveland (23) | F37: 24713 | G37: 0 | H37: Segment both thalami.
... A40: sex | B40: binary | D40: trained | E40: Yale brain metastases (FOMO) (25,058), Healthy Brain Network (FOMO) (5,383), NKI-Rockland (FOMO) (3,426), CoRR (FOMO) (2,001), SLIM longitudinal (FOMO) (771), WAND (FOMO) (597), BrainLat (FOMO) (419), FOMO cohort: nigerian (203), Cuban Human Brain Mapping (FOMO) (153), FOMO cohort: hbnssi (137), FOMO cohort: beijing (135), FOMO cohort: wayne (134), ACPI (FOMO) (123), FOMO cohort: ageility (98), FOMO cohort: yale_highres (93), AHEAD 7T (FOMO) (79), FOMO cohort: cunmet (45), Tao Wu Parkinson's (FOMO) (30), FOMO cohort: cleveland (23) | F40: 38908 | G40: 0 | H40: Is this person male?
A41: stroke_lesion | B41: segmentation | D41: held_out | F41: 0 | G41: 1696 | H41: Segment the stroke lesion.
A42: tumor_core | B42: segmentation | D42: trained | E42: BraTS glioma (2021 / 2023 / 2024 GLI) (6,480), BraTS-MEN 2023 (2,868) | F42: 9348 | G42: 0 | H42: Segment the tumor core: enhancing and necrotic tumor, without edema.
...

Sheet Notes
A1: Item | B1: Meaning
A2: Built | B2: 2026-10-28 from the store index (volumes.csv, sha1 1ab77c50), labels/multitask_v2, brain.downstream.tasks and runs/bench/compare_v2.csv.
A3: Status | B3: In store: preprocessed and indexed. In pool, not prepared: raw archive downloaded. Access granted / Apply / Public download: not yet downloaded. Candidate: under consideration. Unidentified: named by a paper but not found.
A4: SSL pool | B4: Volumes SSL pretraining reads: split == train AND pretrain AND ssl_keep. CQ500, ATLAS, ISLES'24, VALDO and MSD are evaluation-only (pretrain = False).
A5: Benchmark v2 | B5: 22 frozen-readout transfer tasks + 4 segmentation tasks (configs/bench/benchmark.yaml). Suite-only tasks run in the full suite but were left out by the 2026-10-25 selection rule; the Status column gives the reason.
A6: Scores | B6: Test score in the task's metric with the pinned readout. Blank: not run, other modality, or labels seen in training (rsna_ich for BQ models).
A7: External sizes | B7: Approximate, from publications or challenge pages; check the source before use.
A8: Planned tasks | B8: Proposed names for tasks the external datasets would add; not yet defined in the code.
